const catchError = require('../utils/catchError')
const User = require('../models/User')

const getAll = catchError(async (req, res) => {
  // Operaciones...
  const result = await User.findAll() //Select * from users
  return res.json(result)
})

const create = catchError(async (req, res) => {
  const result = await User.create(req.body)
  return res.status(201).json(result)
})

const getOne = catchError(async (req, res) => {
  //const id = req.params.id -> desestructuraciÃ³n sig.linea
  const { id } = req.params
  const result = await User.findByPk(id)
  //! AGREGAR VALIDACION
  if (!result) return res.status(404).json('User not found')
  return res.json(result)
})

const destroy = catchError(async (req, res) => {
  const { id } = req.params
  const result = await User.destroy({ where: { id } })
  if (!result) return res.status(404).json('User not found')
  return res.sendStatus(204)
})

module.exports = {
  getAll,
  create,
  getOne,
  destroy
}
